[2024-04-14T14:44:33.282+0000] {taskinstance.py:1979} INFO - Dependencies all met for dep_context=non-requeueable deps ti=<TaskInstance: prioritas_2.write_to_txt scheduled__2024-04-13T00:00:00+00:00 [queued]>
[2024-04-14T14:44:33.299+0000] {taskinstance.py:1979} INFO - Dependencies all met for dep_context=requeueable deps ti=<TaskInstance: prioritas_2.write_to_txt scheduled__2024-04-13T00:00:00+00:00 [queued]>
[2024-04-14T14:44:33.300+0000] {taskinstance.py:2193} INFO - Starting attempt 1 of 4
[2024-04-14T14:44:33.323+0000] {taskinstance.py:2217} INFO - Executing <Task(PythonOperator): write_to_txt> on 2024-04-13 00:00:00+00:00
[2024-04-14T14:44:33.335+0000] {standard_task_runner.py:60} INFO - Started process 94 to run task
[2024-04-14T14:44:33.342+0000] {standard_task_runner.py:87} INFO - Running: ['***', 'tasks', 'run', 'prioritas_2', 'write_to_txt', 'scheduled__2024-04-13T00:00:00+00:00', '--job-id', '211', '--raw', '--subdir', 'DAGS_FOLDER/prioritas_2_dag.py', '--cfg-path', '/tmp/tmp8t814ppc']
[2024-04-14T14:44:33.347+0000] {standard_task_runner.py:88} INFO - Job 211: Subtask write_to_txt
[2024-04-14T14:44:33.453+0000] {task_command.py:423} INFO - Running <TaskInstance: prioritas_2.write_to_txt scheduled__2024-04-13T00:00:00+00:00 [running]> on host b46e24c16c09
[2024-04-14T14:44:33.606+0000] {taskinstance.py:2513} INFO - Exporting env vars: AIRFLOW_CTX_DAG_OWNER='dzikri' AIRFLOW_CTX_DAG_ID='prioritas_2' AIRFLOW_CTX_TASK_ID='write_to_txt' AIRFLOW_CTX_EXECUTION_DATE='2024-04-13T00:00:00+00:00' AIRFLOW_CTX_TRY_NUMBER='1' AIRFLOW_CTX_DAG_RUN_ID='scheduled__2024-04-13T00:00:00+00:00'
[2024-04-14T14:44:33.631+0000] {taskinstance.py:2731} ERROR - Task failed with exception
Traceback (most recent call last):
  File "/home/airflow/.local/lib/python3.8/site-packages/airflow/models/taskinstance.py", line 444, in _execute_task
    result = _execute_callable(context=context, **execute_callable_kwargs)
  File "/home/airflow/.local/lib/python3.8/site-packages/airflow/models/taskinstance.py", line 414, in _execute_callable
    return execute_callable(context=context, **execute_callable_kwargs)
  File "/home/airflow/.local/lib/python3.8/site-packages/airflow/operators/python.py", line 200, in execute
    return_value = self.execute_callable()
  File "/home/airflow/.local/lib/python3.8/site-packages/airflow/operators/python.py", line 217, in execute_callable
    return self.python_callable(*self.op_args, **self.op_kwargs)
  File "/opt/airflow/dags/prioritas_2_dag.py", line 30, in write_to_txt
    with open(file_path, 'w') as txt_file:
FileNotFoundError: [Errno 2] No such file or directory: '/data/output/products.txt'
[2024-04-14T14:44:33.653+0000] {taskinstance.py:1149} INFO - Marking task as UP_FOR_RETRY. dag_id=prioritas_2, task_id=write_to_txt, execution_date=20240413T000000, start_date=20240414T144433, end_date=20240414T144433
[2024-04-14T14:44:33.680+0000] {standard_task_runner.py:107} ERROR - Failed to execute job 211 for task write_to_txt ([Errno 2] No such file or directory: '/data/output/products.txt'; 94)
[2024-04-14T14:44:33.716+0000] {local_task_job_runner.py:234} INFO - Task exited with return code 1
[2024-04-14T14:44:33.766+0000] {taskinstance.py:3312} INFO - 0 downstream tasks scheduled from follow-on schedule check
