[2024-04-11T12:43:03.551+0000] {taskinstance.py:1979} INFO - Dependencies all met for dep_context=non-requeueable deps ti=<TaskInstance: prioritas2.write_to_pd manual__2024-04-11T12:42:57.645226+00:00 [queued]>
[2024-04-11T12:43:03.567+0000] {taskinstance.py:1979} INFO - Dependencies all met for dep_context=requeueable deps ti=<TaskInstance: prioritas2.write_to_pd manual__2024-04-11T12:42:57.645226+00:00 [queued]>
[2024-04-11T12:43:03.568+0000] {taskinstance.py:2193} INFO - Starting attempt 1 of 6
[2024-04-11T12:43:03.585+0000] {taskinstance.py:2217} INFO - Executing <Task(PythonOperator): write_to_pd> on 2024-04-11 12:42:57.645226+00:00
[2024-04-11T12:43:03.598+0000] {standard_task_runner.py:60} INFO - Started process 1068 to run task
[2024-04-11T12:43:03.601+0000] {standard_task_runner.py:87} INFO - Running: ['***', 'tasks', 'run', 'prioritas2', 'write_to_pd', 'manual__2024-04-11T12:42:57.645226+00:00', '--job-id', '105', '--raw', '--subdir', 'DAGS_FOLDER/prioritas_2_dag.py', '--cfg-path', '/tmp/tmpcrrcztqg']
[2024-04-11T12:43:03.603+0000] {standard_task_runner.py:88} INFO - Job 105: Subtask write_to_pd
[2024-04-11T12:43:03.663+0000] {task_command.py:423} INFO - Running <TaskInstance: prioritas2.write_to_pd manual__2024-04-11T12:42:57.645226+00:00 [running]> on host 37bb2da634e2
[2024-04-11T12:43:03.758+0000] {taskinstance.py:2513} INFO - Exporting env vars: AIRFLOW_CTX_DAG_OWNER='dzikri' AIRFLOW_CTX_DAG_ID='prioritas2' AIRFLOW_CTX_TASK_ID='write_to_pd' AIRFLOW_CTX_EXECUTION_DATE='2024-04-11T12:42:57.645226+00:00' AIRFLOW_CTX_TRY_NUMBER='1' AIRFLOW_CTX_DAG_RUN_ID='manual__2024-04-11T12:42:57.645226+00:00'
[2024-04-11T12:43:03.761+0000] {taskinstance.py:2731} ERROR - Task failed with exception
Traceback (most recent call last):
  File "/home/airflow/.local/lib/python3.8/site-packages/airflow/models/taskinstance.py", line 444, in _execute_task
    result = _execute_callable(context=context, **execute_callable_kwargs)
  File "/home/airflow/.local/lib/python3.8/site-packages/airflow/models/taskinstance.py", line 414, in _execute_callable
    return execute_callable(context=context, **execute_callable_kwargs)
  File "/home/airflow/.local/lib/python3.8/site-packages/airflow/operators/python.py", line 200, in execute
    return_value = self.execute_callable()
  File "/home/airflow/.local/lib/python3.8/site-packages/airflow/operators/python.py", line 217, in execute_callable
    return self.python_callable(*self.op_args, **self.op_kwargs)
  File "/opt/airflow/dags/prioritas_2_dag.py", line 23, in write_to_pd
    df = pd.DataFrame(response_data)
  File "/home/airflow/.local/lib/python3.8/site-packages/pandas/core/frame.py", line 817, in __init__
    raise ValueError("DataFrame constructor not properly called!")
ValueError: DataFrame constructor not properly called!
[2024-04-11T12:43:03.781+0000] {taskinstance.py:1149} INFO - Marking task as UP_FOR_RETRY. dag_id=prioritas2, task_id=write_to_pd, execution_date=20240411T124257, start_date=20240411T124303, end_date=20240411T124303
[2024-04-11T12:43:03.796+0000] {standard_task_runner.py:107} ERROR - Failed to execute job 105 for task write_to_pd (DataFrame constructor not properly called!; 1068)
[2024-04-11T12:43:03.814+0000] {local_task_job_runner.py:234} INFO - Task exited with return code 1
[2024-04-11T12:43:03.838+0000] {taskinstance.py:3312} INFO - 0 downstream tasks scheduled from follow-on schedule check
