[2024-04-11T11:49:06.125+0000] {taskinstance.py:1979} INFO - Dependencies all met for dep_context=non-requeueable deps ti=<TaskInstance: prioritas_1.touch_our_works scheduled__2024-04-09T00:00:00+00:00 [queued]>
[2024-04-11T11:49:06.154+0000] {taskinstance.py:1979} INFO - Dependencies all met for dep_context=requeueable deps ti=<TaskInstance: prioritas_1.touch_our_works scheduled__2024-04-09T00:00:00+00:00 [queued]>
[2024-04-11T11:49:06.156+0000] {taskinstance.py:2193} INFO - Starting attempt 3 of 6
[2024-04-11T11:49:06.217+0000] {taskinstance.py:2217} INFO - Executing <Task(BashOperator): touch_our_works> on 2024-04-09 00:00:00+00:00
[2024-04-11T11:49:06.230+0000] {standard_task_runner.py:60} INFO - Started process 205 to run task
[2024-04-11T11:49:06.240+0000] {standard_task_runner.py:87} INFO - Running: ['***', 'tasks', 'run', 'prioritas_1', 'touch_our_works', 'scheduled__2024-04-09T00:00:00+00:00', '--job-id', '85', '--raw', '--subdir', 'DAGS_FOLDER/prioritas_1_dag.py', '--cfg-path', '/tmp/tmp6j_731hw']
[2024-04-11T11:49:06.251+0000] {standard_task_runner.py:88} INFO - Job 85: Subtask touch_our_works
[2024-04-11T11:49:06.403+0000] {task_command.py:423} INFO - Running <TaskInstance: prioritas_1.touch_our_works scheduled__2024-04-09T00:00:00+00:00 [running]> on host 37bb2da634e2
[2024-04-11T11:49:06.522+0000] {taskinstance.py:2513} INFO - Exporting env vars: AIRFLOW_CTX_DAG_OWNER='dzikri' AIRFLOW_CTX_DAG_ID='prioritas_1' AIRFLOW_CTX_TASK_ID='touch_our_works' AIRFLOW_CTX_EXECUTION_DATE='2024-04-09T00:00:00+00:00' AIRFLOW_CTX_TRY_NUMBER='3' AIRFLOW_CTX_DAG_RUN_ID='scheduled__2024-04-09T00:00:00+00:00'
[2024-04-11T11:49:06.527+0000] {subprocess.py:63} INFO - Tmp dir root location: /tmp
[2024-04-11T11:49:06.529+0000] {subprocess.py:75} INFO - Running command: ['/usr/bin/bash', '-c', 'touch our_works/works.txt']
[2024-04-11T11:49:06.549+0000] {subprocess.py:86} INFO - Output:
[2024-04-11T11:49:06.552+0000] {subprocess.py:93} INFO - touch: cannot touch 'our_works/works.txt': No such file or directory
[2024-04-11T11:49:06.553+0000] {subprocess.py:97} INFO - Command exited with return code 1
[2024-04-11T11:49:06.574+0000] {taskinstance.py:2731} ERROR - Task failed with exception
Traceback (most recent call last):
  File "/home/airflow/.local/lib/python3.8/site-packages/airflow/models/taskinstance.py", line 444, in _execute_task
    result = _execute_callable(context=context, **execute_callable_kwargs)
  File "/home/airflow/.local/lib/python3.8/site-packages/airflow/models/taskinstance.py", line 414, in _execute_callable
    return execute_callable(context=context, **execute_callable_kwargs)
  File "/home/airflow/.local/lib/python3.8/site-packages/airflow/operators/bash.py", line 212, in execute
    raise AirflowException(
airflow.exceptions.AirflowException: Bash command failed. The command returned a non-zero exit code 1.
[2024-04-11T11:49:06.579+0000] {taskinstance.py:1149} INFO - Marking task as UP_FOR_RETRY. dag_id=prioritas_1, task_id=touch_our_works, execution_date=20240409T000000, start_date=20240411T114906, end_date=20240411T114906
[2024-04-11T11:49:06.602+0000] {standard_task_runner.py:107} ERROR - Failed to execute job 85 for task touch_our_works (Bash command failed. The command returned a non-zero exit code 1.; 205)
[2024-04-11T11:49:06.618+0000] {local_task_job_runner.py:234} INFO - Task exited with return code 1
[2024-04-11T11:49:06.654+0000] {taskinstance.py:3312} INFO - 0 downstream tasks scheduled from follow-on schedule check
