[2024-04-11T11:54:49.075+0000] {taskinstance.py:1979} INFO - Dependencies all met for dep_context=non-requeueable deps ti=<TaskInstance: prioritas_1_no_2.generate_random_numbers scheduled__2024-04-09T00:00:00+00:00 [queued]>
[2024-04-11T11:54:49.087+0000] {taskinstance.py:1979} INFO - Dependencies all met for dep_context=requeueable deps ti=<TaskInstance: prioritas_1_no_2.generate_random_numbers scheduled__2024-04-09T00:00:00+00:00 [queued]>
[2024-04-11T11:54:49.088+0000] {taskinstance.py:2193} INFO - Starting attempt 6 of 6
[2024-04-11T11:54:49.107+0000] {taskinstance.py:2217} INFO - Executing <Task(PythonOperator): generate_random_numbers> on 2024-04-09 00:00:00+00:00
[2024-04-11T11:54:49.114+0000] {standard_task_runner.py:60} INFO - Started process 333 to run task
[2024-04-11T11:54:49.118+0000] {standard_task_runner.py:87} INFO - Running: ['***', 'tasks', 'run', 'prioritas_1_no_2', 'generate_random_numbers', 'scheduled__2024-04-09T00:00:00+00:00', '--job-id', '99', '--raw', '--subdir', 'DAGS_FOLDER/prioritas_1_no_2_dag.py', '--cfg-path', '/tmp/tmpowpol6v2']
[2024-04-11T11:54:49.123+0000] {standard_task_runner.py:88} INFO - Job 99: Subtask generate_random_numbers
[2024-04-11T11:54:49.186+0000] {task_command.py:423} INFO - Running <TaskInstance: prioritas_1_no_2.generate_random_numbers scheduled__2024-04-09T00:00:00+00:00 [running]> on host 37bb2da634e2
[2024-04-11T11:54:49.282+0000] {taskinstance.py:2513} INFO - Exporting env vars: AIRFLOW_CTX_DAG_OWNER='dzikri' AIRFLOW_CTX_DAG_ID='prioritas_1_no_2' AIRFLOW_CTX_TASK_ID='generate_random_numbers' AIRFLOW_CTX_EXECUTION_DATE='2024-04-09T00:00:00+00:00' AIRFLOW_CTX_TRY_NUMBER='6' AIRFLOW_CTX_DAG_RUN_ID='scheduled__2024-04-09T00:00:00+00:00'
[2024-04-11T11:54:49.286+0000] {taskinstance.py:2731} ERROR - Task failed with exception
Traceback (most recent call last):
  File "/home/airflow/.local/lib/python3.8/site-packages/airflow/models/taskinstance.py", line 444, in _execute_task
    result = _execute_callable(context=context, **execute_callable_kwargs)
  File "/home/airflow/.local/lib/python3.8/site-packages/airflow/models/taskinstance.py", line 414, in _execute_callable
    return execute_callable(context=context, **execute_callable_kwargs)
  File "/home/airflow/.local/lib/python3.8/site-packages/airflow/operators/python.py", line 200, in execute
    return_value = self.execute_callable()
  File "/home/airflow/.local/lib/python3.8/site-packages/airflow/operators/python.py", line 217, in execute_callable
    return self.python_callable(*self.op_args, **self.op_kwargs)
  File "/opt/airflow/dags/prioritas_1_no_2_dag.py", line 9, in generate_random_numbers
    ti.xcom_push(key="random_numbers")
  File "/home/airflow/.local/lib/python3.8/site-packages/airflow/utils/session.py", line 79, in wrapper
    return func(*args, session=session, **kwargs)
TypeError: xcom_push() missing 1 required positional argument: 'value'
[2024-04-11T11:54:49.306+0000] {taskinstance.py:1149} INFO - Marking task as FAILED. dag_id=prioritas_1_no_2, task_id=generate_random_numbers, execution_date=20240409T000000, start_date=20240411T115449, end_date=20240411T115449
[2024-04-11T11:54:49.321+0000] {standard_task_runner.py:107} ERROR - Failed to execute job 99 for task generate_random_numbers (xcom_push() missing 1 required positional argument: 'value'; 333)
[2024-04-11T11:54:49.373+0000] {local_task_job_runner.py:234} INFO - Task exited with return code 1
[2024-04-11T11:54:49.409+0000] {taskinstance.py:3312} INFO - 0 downstream tasks scheduled from follow-on schedule check
