[2024-04-15T15:55:37.282+0000] {taskinstance.py:1979} INFO - Dependencies all met for dep_context=non-requeueable deps ti=<TaskInstance: prioritas_2.write_to_txt manual__2024-04-15T15:40:23.891422+00:00 [queued]>
[2024-04-15T15:55:37.312+0000] {taskinstance.py:1979} INFO - Dependencies all met for dep_context=requeueable deps ti=<TaskInstance: prioritas_2.write_to_txt manual__2024-04-15T15:40:23.891422+00:00 [queued]>
[2024-04-15T15:55:37.321+0000] {taskinstance.py:2193} INFO - Starting attempt 4 of 4
[2024-04-15T15:55:37.353+0000] {taskinstance.py:2217} INFO - Executing <Task(PythonOperator): write_to_txt> on 2024-04-15 15:40:23.891422+00:00
[2024-04-15T15:55:37.370+0000] {standard_task_runner.py:60} INFO - Started process 823 to run task
[2024-04-15T15:55:37.376+0000] {standard_task_runner.py:87} INFO - Running: ['***', 'tasks', 'run', 'prioritas_2', 'write_to_txt', 'manual__2024-04-15T15:40:23.891422+00:00', '--job-id', '267', '--raw', '--subdir', 'DAGS_FOLDER/prioritas_2_dag.py', '--cfg-path', '/tmp/tmpghosmje9']
[2024-04-15T15:55:37.382+0000] {standard_task_runner.py:88} INFO - Job 267: Subtask write_to_txt
[2024-04-15T15:55:37.467+0000] {task_command.py:423} INFO - Running <TaskInstance: prioritas_2.write_to_txt manual__2024-04-15T15:40:23.891422+00:00 [running]> on host a411a5fcc16a
[2024-04-15T15:55:37.587+0000] {taskinstance.py:2513} INFO - Exporting env vars: AIRFLOW_CTX_DAG_OWNER='dzikri' AIRFLOW_CTX_DAG_ID='prioritas_2' AIRFLOW_CTX_TASK_ID='write_to_txt' AIRFLOW_CTX_EXECUTION_DATE='2024-04-15T15:40:23.891422+00:00' AIRFLOW_CTX_TRY_NUMBER='4' AIRFLOW_CTX_DAG_RUN_ID='manual__2024-04-15T15:40:23.891422+00:00'
[2024-04-15T15:55:37.608+0000] {taskinstance.py:2731} ERROR - Task failed with exception
Traceback (most recent call last):
  File "/home/airflow/.local/lib/python3.8/site-packages/airflow/models/taskinstance.py", line 444, in _execute_task
    result = _execute_callable(context=context, **execute_callable_kwargs)
  File "/home/airflow/.local/lib/python3.8/site-packages/airflow/models/taskinstance.py", line 414, in _execute_callable
    return execute_callable(context=context, **execute_callable_kwargs)
  File "/home/airflow/.local/lib/python3.8/site-packages/airflow/operators/python.py", line 200, in execute
    return_value = self.execute_callable()
  File "/home/airflow/.local/lib/python3.8/site-packages/airflow/operators/python.py", line 217, in execute_callable
    return self.python_callable(*self.op_args, **self.op_kwargs)
  File "/opt/airflow/dags/prioritas_2_dag.py", line 30, in write_to_txt
    with open(file_path, 'w') as txt_file:
FileNotFoundError: [Errno 2] No such file or directory: '/data/output/products.txt'
[2024-04-15T15:55:37.629+0000] {taskinstance.py:1149} INFO - Marking task as FAILED. dag_id=prioritas_2, task_id=write_to_txt, execution_date=20240415T154023, start_date=20240415T155537, end_date=20240415T155537
[2024-04-15T15:55:37.647+0000] {standard_task_runner.py:107} ERROR - Failed to execute job 267 for task write_to_txt ([Errno 2] No such file or directory: '/data/output/products.txt'; 823)
[2024-04-15T15:55:37.672+0000] {local_task_job_runner.py:234} INFO - Task exited with return code 1
[2024-04-15T15:55:37.702+0000] {taskinstance.py:3312} INFO - 0 downstream tasks scheduled from follow-on schedule check
