[2024-04-09T16:20:41.651+0000] {taskinstance.py:1979} INFO - Dependencies all met for dep_context=non-requeueable deps ti=<TaskInstance: prioritas_1_no_2.generate_random_numbers manual__2024-04-09T16:14:31.570687+00:00 [queued]>
[2024-04-09T16:20:41.665+0000] {taskinstance.py:1979} INFO - Dependencies all met for dep_context=requeueable deps ti=<TaskInstance: prioritas_1_no_2.generate_random_numbers manual__2024-04-09T16:14:31.570687+00:00 [queued]>
[2024-04-09T16:20:41.666+0000] {taskinstance.py:2193} INFO - Starting attempt 4 of 6
[2024-04-09T16:20:41.685+0000] {taskinstance.py:2217} INFO - Executing <Task(PythonOperator): generate_random_numbers> on 2024-04-09 16:14:31.570687+00:00
[2024-04-09T16:20:41.692+0000] {standard_task_runner.py:60} INFO - Started process 206 to run task
[2024-04-09T16:20:41.696+0000] {standard_task_runner.py:87} INFO - Running: ['***', 'tasks', 'run', 'prioritas_1_no_2', 'generate_random_numbers', 'manual__2024-04-09T16:14:31.570687+00:00', '--job-id', '59', '--raw', '--subdir', 'DAGS_FOLDER/prioritas_1_no_2_dag.py', '--cfg-path', '/tmp/tmp7xa5ad48']
[2024-04-09T16:20:41.699+0000] {standard_task_runner.py:88} INFO - Job 59: Subtask generate_random_numbers
[2024-04-09T16:20:41.758+0000] {task_command.py:423} INFO - Running <TaskInstance: prioritas_1_no_2.generate_random_numbers manual__2024-04-09T16:14:31.570687+00:00 [running]> on host 37bb2da634e2
[2024-04-09T16:20:41.845+0000] {taskinstance.py:2513} INFO - Exporting env vars: AIRFLOW_CTX_DAG_OWNER='dzikri' AIRFLOW_CTX_DAG_ID='prioritas_1_no_2' AIRFLOW_CTX_TASK_ID='generate_random_numbers' AIRFLOW_CTX_EXECUTION_DATE='2024-04-09T16:14:31.570687+00:00' AIRFLOW_CTX_TRY_NUMBER='4' AIRFLOW_CTX_DAG_RUN_ID='manual__2024-04-09T16:14:31.570687+00:00'
[2024-04-09T16:20:41.849+0000] {taskinstance.py:2731} ERROR - Task failed with exception
Traceback (most recent call last):
  File "/home/airflow/.local/lib/python3.8/site-packages/airflow/models/taskinstance.py", line 444, in _execute_task
    result = _execute_callable(context=context, **execute_callable_kwargs)
  File "/home/airflow/.local/lib/python3.8/site-packages/airflow/models/taskinstance.py", line 414, in _execute_callable
    return execute_callable(context=context, **execute_callable_kwargs)
  File "/home/airflow/.local/lib/python3.8/site-packages/airflow/operators/python.py", line 200, in execute
    return_value = self.execute_callable()
  File "/home/airflow/.local/lib/python3.8/site-packages/airflow/operators/python.py", line 217, in execute_callable
    return self.python_callable(*self.op_args, **self.op_kwargs)
  File "/opt/airflow/dags/prioritas_1_no_2_dag.py", line 9, in generate_random_numbers
    ti.xcom_push(key="random_numbers")
  File "/home/airflow/.local/lib/python3.8/site-packages/airflow/utils/session.py", line 79, in wrapper
    return func(*args, session=session, **kwargs)
TypeError: xcom_push() missing 1 required positional argument: 'value'
[2024-04-09T16:20:41.865+0000] {taskinstance.py:1149} INFO - Marking task as UP_FOR_RETRY. dag_id=prioritas_1_no_2, task_id=generate_random_numbers, execution_date=20240409T161431, start_date=20240409T162041, end_date=20240409T162041
[2024-04-09T16:20:41.881+0000] {standard_task_runner.py:107} ERROR - Failed to execute job 59 for task generate_random_numbers (xcom_push() missing 1 required positional argument: 'value'; 206)
[2024-04-09T16:20:41.911+0000] {local_task_job_runner.py:234} INFO - Task exited with return code 1
[2024-04-09T16:20:41.932+0000] {taskinstance.py:3312} INFO - 0 downstream tasks scheduled from follow-on schedule check
