[2024-04-15T15:40:33.077+0000] {taskinstance.py:1979} INFO - Dependencies all met for dep_context=non-requeueable deps ti=<TaskInstance: prioritas_2.write_to_csv manual__2024-04-15T15:40:27.154650+00:00 [queued]>
[2024-04-15T15:40:33.086+0000] {taskinstance.py:1979} INFO - Dependencies all met for dep_context=requeueable deps ti=<TaskInstance: prioritas_2.write_to_csv manual__2024-04-15T15:40:27.154650+00:00 [queued]>
[2024-04-15T15:40:33.087+0000] {taskinstance.py:2193} INFO - Starting attempt 1 of 4
[2024-04-15T15:40:33.104+0000] {taskinstance.py:2217} INFO - Executing <Task(PythonOperator): write_to_csv> on 2024-04-15 15:40:27.154650+00:00
[2024-04-15T15:40:33.111+0000] {standard_task_runner.py:60} INFO - Started process 558 to run task
[2024-04-15T15:40:33.115+0000] {standard_task_runner.py:87} INFO - Running: ['***', 'tasks', 'run', 'prioritas_2', 'write_to_csv', 'manual__2024-04-15T15:40:27.154650+00:00', '--job-id', '255', '--raw', '--subdir', 'DAGS_FOLDER/prioritas_2_dag.py', '--cfg-path', '/tmp/tmp3p_au24h']
[2024-04-15T15:40:33.118+0000] {standard_task_runner.py:88} INFO - Job 255: Subtask write_to_csv
[2024-04-15T15:40:33.171+0000] {task_command.py:423} INFO - Running <TaskInstance: prioritas_2.write_to_csv manual__2024-04-15T15:40:27.154650+00:00 [running]> on host a411a5fcc16a
[2024-04-15T15:40:33.276+0000] {taskinstance.py:2513} INFO - Exporting env vars: AIRFLOW_CTX_DAG_OWNER='dzikri' AIRFLOW_CTX_DAG_ID='prioritas_2' AIRFLOW_CTX_TASK_ID='write_to_csv' AIRFLOW_CTX_EXECUTION_DATE='2024-04-15T15:40:27.154650+00:00' AIRFLOW_CTX_TRY_NUMBER='1' AIRFLOW_CTX_DAG_RUN_ID='manual__2024-04-15T15:40:27.154650+00:00'
[2024-04-15T15:40:33.302+0000] {taskinstance.py:2731} ERROR - Task failed with exception
Traceback (most recent call last):
  File "/home/airflow/.local/lib/python3.8/site-packages/airflow/models/taskinstance.py", line 444, in _execute_task
    result = _execute_callable(context=context, **execute_callable_kwargs)
  File "/home/airflow/.local/lib/python3.8/site-packages/airflow/models/taskinstance.py", line 414, in _execute_callable
    return execute_callable(context=context, **execute_callable_kwargs)
  File "/home/airflow/.local/lib/python3.8/site-packages/airflow/operators/python.py", line 200, in execute
    return_value = self.execute_callable()
  File "/home/airflow/.local/lib/python3.8/site-packages/airflow/operators/python.py", line 217, in execute_callable
    return self.python_callable(*self.op_args, **self.op_kwargs)
  File "/opt/airflow/dags/prioritas_2_dag.py", line 22, in write_to_csv
    with open(file_path, 'w', newline='') as csv_file:
FileNotFoundError: [Errno 2] No such file or directory: '/data/output/products.csv'
[2024-04-15T15:40:33.320+0000] {taskinstance.py:1149} INFO - Marking task as UP_FOR_RETRY. dag_id=prioritas_2, task_id=write_to_csv, execution_date=20240415T154027, start_date=20240415T154033, end_date=20240415T154033
[2024-04-15T15:40:33.344+0000] {standard_task_runner.py:107} ERROR - Failed to execute job 255 for task write_to_csv ([Errno 2] No such file or directory: '/data/output/products.csv'; 558)
[2024-04-15T15:40:33.368+0000] {local_task_job_runner.py:234} INFO - Task exited with return code 1
[2024-04-15T15:40:33.407+0000] {taskinstance.py:3312} INFO - 0 downstream tasks scheduled from follow-on schedule check
