[2024-04-11T11:51:08.912+0000] {taskinstance.py:1979} INFO - Dependencies all met for dep_context=non-requeueable deps ti=<TaskInstance: prioritas_1.touch_about_us scheduled__2024-04-10T00:00:00+00:00 [queued]>
[2024-04-11T11:51:08.931+0000] {taskinstance.py:1979} INFO - Dependencies all met for dep_context=requeueable deps ti=<TaskInstance: prioritas_1.touch_about_us scheduled__2024-04-10T00:00:00+00:00 [queued]>
[2024-04-11T11:51:08.933+0000] {taskinstance.py:2193} INFO - Starting attempt 4 of 6
[2024-04-11T11:51:08.959+0000] {taskinstance.py:2217} INFO - Executing <Task(BashOperator): touch_about_us> on 2024-04-10 00:00:00+00:00
[2024-04-11T11:51:08.974+0000] {standard_task_runner.py:60} INFO - Started process 259 to run task
[2024-04-11T11:51:08.981+0000] {standard_task_runner.py:87} INFO - Running: ['***', 'tasks', 'run', 'prioritas_1', 'touch_about_us', 'scheduled__2024-04-10T00:00:00+00:00', '--job-id', '91', '--raw', '--subdir', 'DAGS_FOLDER/prioritas_1_dag.py', '--cfg-path', '/tmp/tmp1bd4ez7d']
[2024-04-11T11:51:08.986+0000] {standard_task_runner.py:88} INFO - Job 91: Subtask touch_about_us
[2024-04-11T11:51:09.091+0000] {task_command.py:423} INFO - Running <TaskInstance: prioritas_1.touch_about_us scheduled__2024-04-10T00:00:00+00:00 [running]> on host 37bb2da634e2
[2024-04-11T11:51:09.235+0000] {taskinstance.py:2513} INFO - Exporting env vars: AIRFLOW_CTX_DAG_OWNER='dzikri' AIRFLOW_CTX_DAG_ID='prioritas_1' AIRFLOW_CTX_TASK_ID='touch_about_us' AIRFLOW_CTX_EXECUTION_DATE='2024-04-10T00:00:00+00:00' AIRFLOW_CTX_TRY_NUMBER='4' AIRFLOW_CTX_DAG_RUN_ID='scheduled__2024-04-10T00:00:00+00:00'
[2024-04-11T11:51:09.238+0000] {subprocess.py:63} INFO - Tmp dir root location: /tmp
[2024-04-11T11:51:09.240+0000] {subprocess.py:75} INFO - Running command: ['/usr/bin/bash', '-c', 'touch about_us/about.txt']
[2024-04-11T11:51:09.253+0000] {subprocess.py:86} INFO - Output:
[2024-04-11T11:51:09.257+0000] {subprocess.py:93} INFO - touch: cannot touch 'about_us/about.txt': No such file or directory
[2024-04-11T11:51:09.258+0000] {subprocess.py:97} INFO - Command exited with return code 1
[2024-04-11T11:51:09.274+0000] {taskinstance.py:2731} ERROR - Task failed with exception
Traceback (most recent call last):
  File "/home/airflow/.local/lib/python3.8/site-packages/airflow/models/taskinstance.py", line 444, in _execute_task
    result = _execute_callable(context=context, **execute_callable_kwargs)
  File "/home/airflow/.local/lib/python3.8/site-packages/airflow/models/taskinstance.py", line 414, in _execute_callable
    return execute_callable(context=context, **execute_callable_kwargs)
  File "/home/airflow/.local/lib/python3.8/site-packages/airflow/operators/bash.py", line 212, in execute
    raise AirflowException(
airflow.exceptions.AirflowException: Bash command failed. The command returned a non-zero exit code 1.
[2024-04-11T11:51:09.279+0000] {taskinstance.py:1149} INFO - Marking task as UP_FOR_RETRY. dag_id=prioritas_1, task_id=touch_about_us, execution_date=20240410T000000, start_date=20240411T115108, end_date=20240411T115109
[2024-04-11T11:51:09.299+0000] {standard_task_runner.py:107} ERROR - Failed to execute job 91 for task touch_about_us (Bash command failed. The command returned a non-zero exit code 1.; 259)
[2024-04-11T11:51:09.315+0000] {local_task_job_runner.py:234} INFO - Task exited with return code 1
[2024-04-11T11:51:09.375+0000] {taskinstance.py:3312} INFO - 0 downstream tasks scheduled from follow-on schedule check
