[2024-04-11T11:55:15.916+0000] {taskinstance.py:1979} INFO - Dependencies all met for dep_context=non-requeueable deps ti=<TaskInstance: prioritas_1.touch_about_us scheduled__2024-04-10T00:00:00+00:00 [queued]>
[2024-04-11T11:55:15.943+0000] {taskinstance.py:1979} INFO - Dependencies all met for dep_context=requeueable deps ti=<TaskInstance: prioritas_1.touch_about_us scheduled__2024-04-10T00:00:00+00:00 [queued]>
[2024-04-11T11:55:15.945+0000] {taskinstance.py:2193} INFO - Starting attempt 6 of 6
[2024-04-11T11:55:15.982+0000] {taskinstance.py:2217} INFO - Executing <Task(BashOperator): touch_about_us> on 2024-04-10 00:00:00+00:00
[2024-04-11T11:55:15.997+0000] {standard_task_runner.py:60} INFO - Started process 353 to run task
[2024-04-11T11:55:16.007+0000] {standard_task_runner.py:87} INFO - Running: ['***', 'tasks', 'run', 'prioritas_1', 'touch_about_us', 'scheduled__2024-04-10T00:00:00+00:00', '--job-id', '103', '--raw', '--subdir', 'DAGS_FOLDER/prioritas_1_dag.py', '--cfg-path', '/tmp/tmp7jxk1h50']
[2024-04-11T11:55:16.014+0000] {standard_task_runner.py:88} INFO - Job 103: Subtask touch_about_us
[2024-04-11T11:55:16.147+0000] {task_command.py:423} INFO - Running <TaskInstance: prioritas_1.touch_about_us scheduled__2024-04-10T00:00:00+00:00 [running]> on host 37bb2da634e2
[2024-04-11T11:55:16.336+0000] {taskinstance.py:2513} INFO - Exporting env vars: AIRFLOW_CTX_DAG_OWNER='dzikri' AIRFLOW_CTX_DAG_ID='prioritas_1' AIRFLOW_CTX_TASK_ID='touch_about_us' AIRFLOW_CTX_EXECUTION_DATE='2024-04-10T00:00:00+00:00' AIRFLOW_CTX_TRY_NUMBER='6' AIRFLOW_CTX_DAG_RUN_ID='scheduled__2024-04-10T00:00:00+00:00'
[2024-04-11T11:55:16.340+0000] {subprocess.py:63} INFO - Tmp dir root location: /tmp
[2024-04-11T11:55:16.343+0000] {subprocess.py:75} INFO - Running command: ['/usr/bin/bash', '-c', 'touch about_us/about.txt']
[2024-04-11T11:55:16.362+0000] {subprocess.py:86} INFO - Output:
[2024-04-11T11:55:16.368+0000] {subprocess.py:93} INFO - touch: cannot touch 'about_us/about.txt': No such file or directory
[2024-04-11T11:55:16.369+0000] {subprocess.py:97} INFO - Command exited with return code 1
[2024-04-11T11:55:16.386+0000] {taskinstance.py:2731} ERROR - Task failed with exception
Traceback (most recent call last):
  File "/home/airflow/.local/lib/python3.8/site-packages/airflow/models/taskinstance.py", line 444, in _execute_task
    result = _execute_callable(context=context, **execute_callable_kwargs)
  File "/home/airflow/.local/lib/python3.8/site-packages/airflow/models/taskinstance.py", line 414, in _execute_callable
    return execute_callable(context=context, **execute_callable_kwargs)
  File "/home/airflow/.local/lib/python3.8/site-packages/airflow/operators/bash.py", line 212, in execute
    raise AirflowException(
airflow.exceptions.AirflowException: Bash command failed. The command returned a non-zero exit code 1.
[2024-04-11T11:55:16.393+0000] {taskinstance.py:1149} INFO - Marking task as FAILED. dag_id=prioritas_1, task_id=touch_about_us, execution_date=20240410T000000, start_date=20240411T115515, end_date=20240411T115516
[2024-04-11T11:55:16.414+0000] {standard_task_runner.py:107} ERROR - Failed to execute job 103 for task touch_about_us (Bash command failed. The command returned a non-zero exit code 1.; 353)
[2024-04-11T11:55:16.462+0000] {local_task_job_runner.py:234} INFO - Task exited with return code 1
[2024-04-11T11:55:16.498+0000] {taskinstance.py:3312} INFO - 0 downstream tasks scheduled from follow-on schedule check
