[2024-04-13T19:00:22.796+0000] {taskinstance.py:1979} INFO - Dependencies all met for dep_context=non-requeueable deps ti=<TaskInstance: prioritas_2.write_to_txt manual__2024-04-13T19:00:17.942049+00:00 [queued]>
[2024-04-13T19:00:22.804+0000] {taskinstance.py:1979} INFO - Dependencies all met for dep_context=requeueable deps ti=<TaskInstance: prioritas_2.write_to_txt manual__2024-04-13T19:00:17.942049+00:00 [queued]>
[2024-04-13T19:00:22.805+0000] {taskinstance.py:2193} INFO - Starting attempt 1 of 4
[2024-04-13T19:00:22.818+0000] {taskinstance.py:2217} INFO - Executing <Task(PythonOperator): write_to_txt> on 2024-04-13 19:00:17.942049+00:00
[2024-04-13T19:00:22.823+0000] {standard_task_runner.py:60} INFO - Started process 771 to run task
[2024-04-13T19:00:22.826+0000] {standard_task_runner.py:87} INFO - Running: ['***', 'tasks', 'run', 'prioritas_2', 'write_to_txt', 'manual__2024-04-13T19:00:17.942049+00:00', '--job-id', '189', '--raw', '--subdir', 'DAGS_FOLDER/prioritas_2_dag.py', '--cfg-path', '/tmp/tmpugfez_ue']
[2024-04-13T19:00:22.829+0000] {standard_task_runner.py:88} INFO - Job 189: Subtask write_to_txt
[2024-04-13T19:00:22.874+0000] {task_command.py:423} INFO - Running <TaskInstance: prioritas_2.write_to_txt manual__2024-04-13T19:00:17.942049+00:00 [running]> on host b46e24c16c09
[2024-04-13T19:00:22.939+0000] {taskinstance.py:2513} INFO - Exporting env vars: AIRFLOW_CTX_DAG_OWNER='dzikri' AIRFLOW_CTX_DAG_ID='prioritas_2' AIRFLOW_CTX_TASK_ID='write_to_txt' AIRFLOW_CTX_EXECUTION_DATE='2024-04-13T19:00:17.942049+00:00' AIRFLOW_CTX_TRY_NUMBER='1' AIRFLOW_CTX_DAG_RUN_ID='manual__2024-04-13T19:00:17.942049+00:00'
[2024-04-13T19:00:22.964+0000] {taskinstance.py:2731} ERROR - Task failed with exception
Traceback (most recent call last):
  File "/home/airflow/.local/lib/python3.8/site-packages/airflow/models/taskinstance.py", line 444, in _execute_task
    result = _execute_callable(context=context, **execute_callable_kwargs)
  File "/home/airflow/.local/lib/python3.8/site-packages/airflow/models/taskinstance.py", line 414, in _execute_callable
    return execute_callable(context=context, **execute_callable_kwargs)
  File "/home/airflow/.local/lib/python3.8/site-packages/airflow/operators/python.py", line 200, in execute
    return_value = self.execute_callable()
  File "/home/airflow/.local/lib/python3.8/site-packages/airflow/operators/python.py", line 217, in execute_callable
    return self.python_callable(*self.op_args, **self.op_kwargs)
  File "/opt/airflow/dags/prioritas_2_dag.py", line 30, in write_to_txt
    with open(file_path, 'w') as txt_file:
FileNotFoundError: [Errno 2] No such file or directory: '/data/output/products.txt'
[2024-04-13T19:00:22.980+0000] {taskinstance.py:1149} INFO - Marking task as UP_FOR_RETRY. dag_id=prioritas_2, task_id=write_to_txt, execution_date=20240413T190017, start_date=20240413T190022, end_date=20240413T190022
[2024-04-13T19:00:22.994+0000] {standard_task_runner.py:107} ERROR - Failed to execute job 189 for task write_to_txt ([Errno 2] No such file or directory: '/data/output/products.txt'; 771)
[2024-04-13T19:00:23.040+0000] {local_task_job_runner.py:234} INFO - Task exited with return code 1
[2024-04-13T19:00:23.059+0000] {taskinstance.py:3312} INFO - 0 downstream tasks scheduled from follow-on schedule check
