[2024-04-15T13:38:47.049+0000] {taskinstance.py:1979} INFO - Dependencies all met for dep_context=non-requeueable deps ti=<TaskInstance: prioritas_2.write_to_txt scheduled__2024-04-14T00:00:00+00:00 [queued]>
[2024-04-15T13:38:47.056+0000] {taskinstance.py:1979} INFO - Dependencies all met for dep_context=requeueable deps ti=<TaskInstance: prioritas_2.write_to_txt scheduled__2024-04-14T00:00:00+00:00 [queued]>
[2024-04-15T13:38:47.056+0000] {taskinstance.py:2193} INFO - Starting attempt 2 of 4
[2024-04-15T13:38:47.066+0000] {taskinstance.py:2217} INFO - Executing <Task(PythonOperator): write_to_txt> on 2024-04-14 00:00:00+00:00
[2024-04-15T13:38:47.072+0000] {standard_task_runner.py:60} INFO - Started process 195 to run task
[2024-04-15T13:38:47.075+0000] {standard_task_runner.py:87} INFO - Running: ['***', 'tasks', 'run', 'prioritas_2', 'write_to_txt', 'scheduled__2024-04-14T00:00:00+00:00', '--job-id', '242', '--raw', '--subdir', 'DAGS_FOLDER/prioritas_2_dag.py', '--cfg-path', '/tmp/tmpwi20ck_w']
[2024-04-15T13:38:47.077+0000] {standard_task_runner.py:88} INFO - Job 242: Subtask write_to_txt
[2024-04-15T13:38:47.113+0000] {task_command.py:423} INFO - Running <TaskInstance: prioritas_2.write_to_txt scheduled__2024-04-14T00:00:00+00:00 [running]> on host 962ac5502d16
[2024-04-15T13:38:47.180+0000] {taskinstance.py:2513} INFO - Exporting env vars: AIRFLOW_CTX_DAG_OWNER='dzikri' AIRFLOW_CTX_DAG_ID='prioritas_2' AIRFLOW_CTX_TASK_ID='write_to_txt' AIRFLOW_CTX_EXECUTION_DATE='2024-04-14T00:00:00+00:00' AIRFLOW_CTX_TRY_NUMBER='2' AIRFLOW_CTX_DAG_RUN_ID='scheduled__2024-04-14T00:00:00+00:00'
[2024-04-15T13:38:47.191+0000] {taskinstance.py:2731} ERROR - Task failed with exception
Traceback (most recent call last):
  File "/home/airflow/.local/lib/python3.8/site-packages/airflow/models/taskinstance.py", line 444, in _execute_task
    result = _execute_callable(context=context, **execute_callable_kwargs)
  File "/home/airflow/.local/lib/python3.8/site-packages/airflow/models/taskinstance.py", line 414, in _execute_callable
    return execute_callable(context=context, **execute_callable_kwargs)
  File "/home/airflow/.local/lib/python3.8/site-packages/airflow/operators/python.py", line 200, in execute
    return_value = self.execute_callable()
  File "/home/airflow/.local/lib/python3.8/site-packages/airflow/operators/python.py", line 217, in execute_callable
    return self.python_callable(*self.op_args, **self.op_kwargs)
  File "/opt/airflow/dags/prioritas_2_dag.py", line 30, in write_to_txt
    with open(file_path, 'w') as txt_file:
FileNotFoundError: [Errno 2] No such file or directory: '/data/output/products.txt'
[2024-04-15T13:38:47.201+0000] {taskinstance.py:1149} INFO - Marking task as UP_FOR_RETRY. dag_id=prioritas_2, task_id=write_to_txt, execution_date=20240414T000000, start_date=20240415T133847, end_date=20240415T133847
[2024-04-15T13:38:47.211+0000] {standard_task_runner.py:107} ERROR - Failed to execute job 242 for task write_to_txt ([Errno 2] No such file or directory: '/data/output/products.txt'; 195)
[2024-04-15T13:38:47.247+0000] {local_task_job_runner.py:234} INFO - Task exited with return code 1
[2024-04-15T13:38:47.266+0000] {taskinstance.py:3312} INFO - 0 downstream tasks scheduled from follow-on schedule check
